Workbook
Name _1B.05.M.010.0010: #REF!
Name _1B.05.M.010.0010: #REF!
Name _1B.05.M.010.0010: #REF!
Name _1B.05.M.010.0050: #REF!
Name _1B.05.M.010.0050: #REF!
Name _1B.05.M.0100.0010: #REF!
Name _1B.05.M.0100.0010: #REF!
Name _1B.05.M.020.0010: #REF!
Name _1B.05.M.020.0010: #REF!
Name _1B.05.M.020.0020: #REF!
Name _1B.05.M.020.0020: #REF!
Name _1B.05.M.020.0030: #REF!
Name _1B.05.M.020.0030: #REF!
Name _1B.05.M.020.0040: #REF!
Name _1B.05.M.020.0040: #REF!
Name _1B.05.M.030.0010: #REF!
Name _1B.05.M.030.0010: #REF!
Name _1B.05.M.030.0020: #REF!
Name _1B.05.M.030.0020: #REF!
Name _1B.05.M.040.0010: #REF!
Name _1B.05.M.040.0010: #REF!
Name _1B.05.M.050.0010: #REF!
Name _1B.05.M.050.0010: #REF!
Name _1B.05.M.050.0020: #REF!
Name _1B.05.M.050.0020: #REF!
Name _1B.05.M.050.0030: #REF!
Name _1B.05.M.050.0030: #REF!
Name _1B.05.M.060.0020: #REF!
Name _1B.05.M.060.0020: #REF!
Name _1B.05.M.060.0100: #REF!
Name _1B.05.M.060.0100: #REF!
Name _1B.05.M.070.0010: #REF!
Name _1B.05.M.070.0010: #REF!
Name _1B.05.M.070.0020: #REF!
Name _1B.05.M.070.0020: #REF!
Name _1B.05.M.070.0030: #REF!
Name _1B.05.M.070.0030: #REF!
Name _1B.05.M.070.0040: #REF!
Name _1B.05.M.070.0040: #REF!
Name _1B.05.M.070.0050: #REF!
Name _1B.05.M.070.0050: #REF!
Name _1B.05.M.080.0010: #REF!
Name _1B.05.M.080.0010: #REF!
Name _1B.05.M.090.0010: #REF!
Name _1B.05.M.090.0010: #REF!
Name _1B.09.P.010.0010: #REF!
Name _1B.09.P.010.0010: #REF!
Name _1B.09.P.010.0020: #REF!
Name _1B.09.P.010.0020: #REF!
Name _1B.09.P.010.0030: #REF!
Name _1B.09.P.010.0030: #REF!
Name _1B.09.P.010.0040: #REF!
Name _1B.09.P.010.0040: #REF!
Name _1B.09.P.010.0050: #REF!
Name _1B.09.P.010.0050: #REF!
Name _1B.09.P.010.0060: #REF!
Name _1B.09.P.010.0060: #REF!
Name _1B.09.P.010.0070: #REF!
Name _1B.09.P.010.0070: #REF!
Name _1B.09.P.020.0010: #REF!

Sheet Weekly Progress Report
A1: MODON - Weekly Progress Report - Construction Projects | AF1: Data Date | AG1: ='General Information'!L1 -> 46314
A2: Contract General Information | G2: Key Dates | M2: Cost Summary (SR) | U2: Performance Summary | AA2: Project Scope
A3: Project Name | B3: ='General Information'!C3 -> Construction of Passenger Station for SAR Railway Sudair Industrial City | G3: Contract Award | H3: ='General Information'!C12 -> 46112 | I3: Contract Award (Hijri) | J3: ='General Information'!C16 -> 10/12/1447 | K3: Revised Completion | L3: ='General Information'!C20 -> 46119 | M3: Original Contract Value | O3: ='Invoice Log'!F3 -> 33090825 | Q3: O&M Value | S3: ='Invoice Log'!J3 -> 0 | T3: EAC | U3: Plan Value | V3: =K44 -> 0.19043972 | W3: Phys. Plan Value | X3: =W44 -> 0.38056579 | Y3: Quality Score | Z3: =Quality.!AC10 -> 0.88724138 | AA3: Civil Work , Storm Water Drainage , Sewer , Portable , Electrical , CCTV
A4: Project ID | B4: ='General Information'!C4 -> SUD1-05-018 | D4: Stage | E4: ='General Information'!C7 -> Construction | G4: Contract Sign | H4: ='General Information'!C13 -> 46112 | I4: Contract Sign (Hijri) | J4: ='General Information'!C17 -> 10/12/1447 | K4: Committed Completion | L4: ='General Information'!C21 -> 46605 | M4: Revised Contract Value | O4: ='Invoice Log'!F4 -> 0 | P4: EAC | Q4: Revised O&M Value | S4: ='Invoice Log'!J4 -> 0 | T4: =+#REF!+#REF!+S4 -> #REF! | U4: Earn Value | V4: =L44 -> 0.21442627 | W4: Phys. Earn Value | X4: =X44 -> 0.2607931 | Z4: =REPT("¢",IF(INT(+Z3*10)>5,5,INT(+Z3*10)))&REPT("£",IF(INT(+Z3*10)>5,0,5-INT(+Z3*10)))&CHAR(10)&REPT("¢",+IF(INT(+Z3*10)>5,-5+INT(+Z3*10),0))&REPT("£",IF(INT(+Z3*10)>5,10-INT(+Z3*10),5)) -> ¢¢¢¢¢ ¢¢¢££
A5: Contractor | B5: ='General Information'!C5 -> Technical Dvelopment Co. "TDC" | D5: Status | E5: ='General Information'!C8 -> Active | G5: Site Handover | H5: ='General Information'!C14 -> 46119 | I5: Site Handover (Hijri) | J5: ='General Information'!C18 -> 11/19/1447 | K5: Forecast Completion | L5: ='General Information'!C22 -> 46605 | M5: Estimate At Completion Value | O5: ='Invoice Log'!F5 -> 33090825 | P5: =+#REF!+#REF!+O5 -> #REF! | Q5: Submitted Invoices (Gross Value) | S5: ='Invoice Log'!J5 -> 3048399.3 | U5: Variance | V5: =V4-V3 -> 0.023986546 | W5: Variance | X5: =X4-X3 -> -0.11977268 | Y5: Safety Score | Z5: =HSE.!AE6 -> 0.83333333
A6: Consultant | B6: ='General Information'!C6 -> Saudi Arabia Consulting Engineering Company "EGIS" | D6: Modon PM | E6: ='General Information'!C9 -> Engr.Zyad Al Shabat | G6: Original Completion | H6: ='General Information'!C15 -> 46605 | I6: Original Completion (Hijri) | J6: ='General Information'!C19 -> 03/03/1449 | K6: Variance | L6: ='General Information'!C23 -> 0 | M6: Potential Changes | O6: ='Invoice Log'!F6 -> 0 | Q6: Total Deduction | S6: ='Invoice Log'!J6 -> -2000 | U6: SPI | V6: =N44 -> 1.1259535 | W6: SPI | X6: =Z44 -> 0.68527733 | Z6: =REPT("¢",IF(INT(+Z5*10)>5,5,INT(+Z5*10)))&REPT("£",IF(INT(+Z5*10)>5,0,5-INT(+Z5*10)))&CHAR(10)&REPT("¢",+IF(INT(+Z5*10)>5,-5+INT(+Z5*10),0))&REPT("£",IF(INT(+Z5*10)>5,10-INT(+Z5*10),5)) -> ¢¢¢¢¢ ¢¢¢££
A8: Progress Overview
A9: Earned Value Progress (SAR) | O9: Physical Progress (Effort) | AA9: Earned Value Progress (%)
A10: WBS | C10: BOQ Value (SAR) | D10: % Wt. | E10: Weekly (SAR) | G10: To Date (SAR) | O10: Budgeted | P10: % Wt. | Q10: Weekly Physical Progress | U10: To Date Physical Progress
E11: Planned | F11: Earned | G11: Original Plan | H11: Cum. Planned | I11: Cum.Earned | J11: Original Plan % | K11: Cum. Planned % | L11: Cum.Earned % | M11: Variance | N11: SPI | O11: (Manhours) | Q11: Planned | R11: Earned | S11: Plan % | T11: Earned % | U11: Planned | V11: Earned | W11: Plan % | X11: Earned % | Y11: Variance | Z11: SPI
C12: =Progress!C7 -> 0 | D12: =Progress!D7 -> 0 | E12: =Progress!E39 -> 0 | F12: =Progress!F39 -> 0 | G12: =Progress!G39 -> 0 | H12: =Progress!H39 -> 22585.02 | I12: =Progress!I39 -> 0 | J12: =IFERROR(IF(ISBLANK(G12),"",G12/C12),0) -> 0 | K12: =IFERROR(IF(ISBLANK(H12),"",H12/C12),0) -> 0 | L12: =IFERROR(IF(ISBLANK(I12),"",I12/C12),0) -> 0 | M12: =IFERROR(L12-K12,"") -> 0 | N12: =IFERROR(L12/K12,"") | O12: =Progress!K7 -> 0 | P12: =IF(ISBLANK(O12),"",O12/$O$44) -> 0 | Q12: =Progress!M7 -> 0 | R12: =Progress!N7 -> 0 | S12: =IFERROR(IF(ISBLANK(Q12),"",Q12/O12),0) -> 0 | T12: =IFERROR(IF(ISBLANK(R12),"",R12/O12),0) -> 0 | U12: =Progress!O7 -> 0 | V12: =Progress!P7 -> 0 | W12: =IFERROR(IF(ISBLANK(U12),"",U12/O12),0) -> 0 | X12: =IFERROR(IF(ISBLANK(V12),"",V12/O12),0) -> 0 | Y12: =IFERROR(X12-W12,"") -> 0 | Z12: =IFERROR(X12/W12,"")
A13: =Progress!A7 -> Milestones | C13: =Progress!C8 -> 0 | D13: =Progress!D8 -> 0 | E13: =Progress!E40 -> 0 | F13: =Progress!F8 -> 0 | G13: =Progress!G8 -> 0 | H13: =Progress!H8 -> 0 | I13: =Progress!I8 -> 0 | J13: =IFERROR(IF(ISBLANK(G13),"",G13/C13),0) -> 0 | K13: =IFERROR(IF(ISBLANK(H13),"",H13/C13),0) -> 0 | L13: =IFERROR(IF(ISBLANK(I13),"",I13/C13),0) -> 0 | M13: =IFERROR(L13-K13,"") -> 0 | N13: =IFERROR(L13/K13,"") | O13: =Progress!K7 -> 0 | P13: =IF(ISBLANK(O13),"",O13/$O$44) -> 0 | Q13: =Progress!M8 -> 0 | R13: =Progress!N8 -> 0 | S13: =IFERROR(IF(ISBLANK(Q13),"",Q13/O13),0) -> 0 | T13: =IFERROR(IF(ISBLANK(R13),"",R13/O13),0) -> 0 | U13: =Progress!O8 -> 19793 | V13: =Progress!P8 -> 19793 | W13: =IFERROR(IF(ISBLANK(U13),"",U13/O13),0) -> 0 | X13: =IFERROR(IF(ISBLANK(V13),"",V13/O13),0) -> 0 | Y13: =IFERROR(X13-W13,"") -> 0 | Z13: =IFERROR(X13/W13,"")
A14: =Progress!A8 -> Mobilization | C14: =Progress!C8 -> 0 | D14: =Progress!D8 -> 0 | E14: =Progress!E9 -> 0 | F14: =Progress!F8 -> 0 | G14: =Progress!G9 -> 0 | H14: =Progress!H8 -> 0 | I14: =Progress!I8 -> 0 | J14: =IFERROR(IF(ISBLANK(G14),"",G14/C14),0) -> 0 | K14: =IFERROR(IF(ISBLANK(H14),"",H14/C14),0) -> 0 | L14: =IFERROR(IF(ISBLANK(I14),"",I14/C14),0) -> 0 | M14: =Progress!M8 -> 0 | N14: =IFERROR(L14/K14,"") | O14: =Progress!K8 -> 19154 | P14: =Progress!L8 -> 0.029999947 | Q14: =Progress!Q8 -> 0 | R14: =Progress!R8 -> 0 | S14: =Progress!S8 -> 0 | T14: =Progress!T8 -> 0 | U14: =Progress!U8 -> 0 | V14: =Progress!V8 -> 0 | W14: =Progress!W8 -> 0 | X14: =Progress!X8 -> 0 | Y14: =Progress!Y8 -> 0 | Z14: =IFERROR(X14/W14,"")
A15: =Progress!A9 -> Engineering | C15: =Progress!C9 -> 0 | D15: =Progress!D9 -> 0 | E15: =Progress!E9 -> 0 | F15: =Progress!F9 -> 0 | G15: =Progress!G9 -> 0 | H15: =Progress!H9 -> 0 | I15: =Progress!I9 -> 0 | J15: =IFERROR(IF(ISBLANK(G15),"",G15/C15),0) -> 0 | K15: =IFERROR(IF(ISBLANK(H15),"",H15/C15),0) -> 0 | L15: =IFERROR(IF(ISBLANK(I15),"",I15/C15),0) -> 0 | M15: =IFERROR(L15-K15,"") -> 0 | N15: =IFERROR(L15/K15,"") | O15: =Progress!K9 -> 31923.4 | P15: =IF(ISBLANK(O15),"",O15/$O$44) -> 0.050000016 | Q15: =Progress!M9 -> 0 | R15: =Progress!N9 -> 0 | S15: =IFERROR(IF(ISBLANK(Q15),"",Q15/O15),0) -> 0 | T15: =IFERROR(IF(ISBLANK(R15),"",R15/O15),0) -> 0 | U15: =Progress!O9 -> 32988 | V15: =Progress!P9 -> 31339 | W15: =IFERROR(IF(ISBLANK(U15),"",U15/O15),0) -> 1.0333486 | X15: =IFERROR(IF(ISBLANK(V15),"",V15/O15),0) -> 0.98169368 | Y15: =IFERROR(X15-W15,"") -> -0.051654899 | Z15: =IFERROR(X15/W15,"") -> 0.95001213
A16: =Progress!A10 -> Procurement | C16: =Progress!C10 -> 0 | D16: =Progress!D10 -> 0 | E16: =Progress!E10 -> 0 | F16: =Progress!F10 -> 0 | G16: =Progress!G10 -> 0 | H16: =Progress!H10 -> 0 | I16: =Progress!I10 -> 0 | J16: =IFERROR(IF(ISBLANK(G16),"",G16/C16),0) -> 0 | K16: =IFERROR(IF(ISBLANK(H16),"",H16/C16),0) -> 0 | L16: =IFERROR(IF(ISBLANK(I16),"",I16/C16),0) -> 0 | M16: =IFERROR(L16-K16,"") -> 0 | N16: =IFERROR(L16/K16,"") | O16: =Progress!K10 -> 89385.5 | P16: =IF(ISBLANK(O16),"",O16/$O$44) -> 0.14000001 | Q16: =Progress!M10 -> 3134 | R16: =Progress!N10 -> 4642 | S16: =IFERROR(IF(ISBLANK(Q16),"",Q16/O16),0) -> 0.035061615 | T16: =IFERROR(IF(ISBLANK(R16),"",R16/O16),0) -> 0.05193236 | U16: =Progress!O10 -> 68347 | V16: =Progress!P10 -> 17130 | W16: =IFERROR(IF(ISBLANK(U16),"",U16/O16),0) -> 0.76463185 | X16: =IFERROR(IF(ISBLANK(V16),"",V16/O16),0) -> 0.19164182 | Y16: =IFERROR(X16-W16,"") -> -0.57299003 | Z16: =IFERROR(X16/W16,"") -> 0.2506328
A17: =Progress!A11 -> Construction | C17: =Progress!C11 -> 33090852 | D17: =Progress!D11 -> 1 | E17: =Progress!E11 -> 710697.41 | F17: =Progress!F11 -> 214091.03 | G17: =Progress!G11 -> 0 | H17: =Progress!H11 -> 6301807.5 | I17: =Progress!I11 -> 7095542 | J17: =IFERROR(IF(ISBLANK(G17),"",G17/C17),0) -> 0 | K17: =IFERROR(IF(ISBLANK(H17),"",H17/C17),0) -> 0.19043956 | L17: =IFERROR(IF(ISBLANK(I17),"",I17/C17),0) -> 0.21442609 | M17: =IFERROR(L17-K17,"") -> 0.023986526 | N17: =IFERROR(L17/K17,"") -> 1.1259535 | O17: =Progress!K11 -> 478850.8 | P17: =IF(ISBLANK(O17),"",O17/$O$44) -> 0.74999992 | Q17: =Progress!M11 -> 8552 | R17: =Progress!N11 -> 3430 | S17: =IFERROR(IF(ISBLANK(Q17),"",Q17/O17),0) -> 0.017859425 | T17: =IFERROR(IF(ISBLANK(R17),"",R17/O17),0) -> 0.0071629827 | U17: =Progress!O11 -> 121851 | V17: =Progress!P11 -> 98246 | W17: =IFERROR(IF(ISBLANK(U17),"",U17/O17),0) -> 0.25446548 | X17: =IFERROR(IF(ISBLANK(V17),"",V17/O17),0) -> 0.20517038 | Y17: =IFERROR(X17-W17,"") -> -0.049295104 | Z17: =IFERROR(X17/W17,"") -> 0.8062798
A18: =Progress!A12 -> Package-1 | C18: =Progress!C12 -> 22502032 | D18: =Progress!D12 -> 0.68000763 | E18: =Progress!E12 -> 613731.64 | F18: =Progress!F12 -> 214091.03 | G18: =Progress!G12 -> 0 | H18: =Progress!H12 -> 5886632.1 | I18: =Progress!I12 -> 7095542 | J18: =IFERROR(IF(ISBLANK(G18),"",G18/C18),0) -> 0 | K18: =IFERROR(IF(ISBLANK(H18),"",H18/C18),0) -> 0.26160447 | L18: =IFERROR(IF(ISBLANK(I18),"",I18/C18),0) -> 0.31532895 | M18: =IFERROR(L18-K18,"") -> 0.053724478 | N18: =IFERROR(L18/K18,"") -> 1.2053653 | O18: =Progress!K12 -> 345775.5 | P18: =IF(ISBLANK(O18),"",O18/$O$44) -> 0.54157077 | Q18: =Progress!M12 -> 8143 | R18: =Progress!N12 -> 3430 | S18: =IFERROR(IF(ISBLANK(Q18),"",Q18/O18),0) -> 0.023549962 | T18: =IFERROR(IF(ISBLANK(R18),"",R18/O18),0) -> 0.0099197312 | U18: =Progress!O12 -> 109662 | V18: =Progress!P12 -> 98246 | W18: =IFERROR(IF(ISBLANK(U18),"",U18/O18),0) -> 0.31714798 | X18: =IFERROR(IF(ISBLANK(V18),"",V18/O18),0) -> 0.28413233 | Y18: =IFERROR(X18-W18,"") -> -0.033015642 | Z18: =IFERROR(X18/W18,"") -> 0.89589831
A19: =Progress!A13 -> ROAD WORKS 1 | C19: =Progress!C13 -> 17704263 | D19: =Progress!D13 -> 0.53501986 | E19: =Progress!E13 -> 514154.16 | F19: =Progress!F13 -> 111822.59 | G19: =Progress!G13 -> 0 | H19: =Progress!H13 -> 5366361.2 | I19: =Progress!I13 -> 6500573.5 | J19: =IFERROR(IF(ISBLANK(G19),"",G19/C19),0) -> 0 | K19: =IFERROR(IF(ISBLANK(H19),"",H19/C19),0) -> 0.30311124 | L19: =IFERROR(IF(ISBLANK(I19),"",I19/C19),0) -> 0.36717561 | M19: =IFERROR(L19-K19,"") -> 0.064064363 | N19: =IFERROR(L19/K19,"") -> 1.2113559 | O19: =Progress!K13 -> 168659.6 | P19: =IF(ISBLANK(O19),"",O19/$O$44) -> 0.26416305 | Q19: =Progress!M13 -> 15867 | R19: =Progress!N13 -> 557 | S19: =IFERROR(IF(ISBLANK(Q19),"",Q19/O19),0) -> 0.094077064 | T19: =IFERROR(IF(ISBLANK(R19),"",R19/O19),0) -> 0.0033025099 | U19: =Progress!O13 -> 73549 | V19: =Progress!P13 -> 78905 | W19: =IFERROR(IF(ISBLANK(U19),"",U19/O19),0) -> 0.43607954 | X19: =IFERROR(IF(ISBLANK(V19),"",V19/O19),0) -> 0.46783581 | Y19: =IFERROR(X19-W19,"") -> 0.031756271 | Z19: =IFERROR(X19/W19,"") -> 1.0728222
A20: =Progress!A14 -> ROAD - 01 | C20: =Progress!C14 -> 10400905 | D20: =Progress!D14 -> 0.31431361 | E20: =Progress!E14 -> 275854.68 | F20: =Progress!F14 -> 111822.59 | G20: =Progress!G14 -> 0 | H20: =Progress!H14 -> 3150987.4 | I20: =Progress!I14 -> 4140066.2 | J20: =IFERROR(IF(ISBLANK(G20),"",G20/C20),0) -> 0 | K20: =IFERROR(IF(ISBLANK(I20),"",I20/C20),0) -> 0.39804865 | L20: =IFERROR(IF(ISBLANK(I20),"",I20/C20),0) -> 0.39804865 | M20: =IFERROR(L20-K20,"") -> 0 | N20: =IFERROR(L20/K20,"") -> 1 | O20: =Progress!K14 -> 96629.6 | P20: =IF(ISBLANK(O20),"",O20/$O$44) -> 0.15134608 | Q20: =Progress!M14 -> 1058 | R20: =Progress!N14 -> 557 | S20: =IFERROR(IF(ISBLANK(Q20),"",Q20/O20),0) -> 0.010949026 | T20: =IFERROR(IF(ISBLANK(R20),"",R20/O20),0) -> 0.0057642793 | U20: =Progress!O14 -> 58740 | V20: =Progress!P14 -> 62660 | W20: =IFERROR(IF(ISBLANK(U20),"",U20/O20),0) -> 0.60788827 | X20: =IFERROR(IF(ISBLANK(V20),"",V20/O20),0) -> 0.64845555 | Y20: =IFERROR(X20-W20,"") -> 0.04056728 | Z20: =IFERROR(X20/W20,"") -> 1.0667348
A21: =Progress!A15 -> ROAD - 02 | C21: =Progress!C15 -> 7303358 | D21: =Progress!D15 -> 0.22070625 | E21: =Progress!E15 -> 238299.48 | F21: =Progress!F15 -> 0 | H21: =Progress!H15 -> 2215373.7 | I21: =Progress!I15 -> 2360507.3 | O21: =Progress!K15 -> 72030.1 | P21: =IF(ISBLANK(O21),"",O21/$O$44) -> 0.11281712 | Q21: =Progress!M15 -> 1164 | R21: =Progress!N15 -> 0 | S21: =IFERROR(IF(ISBLANK(Q21),"",Q21/O21),0) -> 0.016159911 | T21: =IFERROR(IF(ISBLANK(R21),"",R21/O21),0) -> 0 | U21: =Progress!O15 -> 14810 | V21: =Progress!P15 -> 16245 | W21: =IFERROR(IF(ISBLANK(U21),"",U21/O21),0) -> 0.20560849 | X21: =IFERROR(IF(ISBLANK(V21),"",V21/O21),0) -> 0.22553072 | Y21: =IFERROR(X21-W21,"") -> 0.019922227 | Z21: =IFERROR(X21/W21,"") -> 1.096894
A22: =Progress!A16 -> ELECTRICAL WORKS | C22: =Progress!C16 -> 3415753 | D22: =Progress!D16 -> 0.10322348 | E22: =Progress!E16 -> 62394.6 | F22: =Progress!F16 -> 43659.79 | H22: =Progress!H16 -> 246971.83 | I22: =Progress!I16 -> 62629.37 | O22: =Progress!K16 -> 103222.1 | P22: =IF(ISBLANK(O22),"",O22/$O$44) -> 0.16167158 | Q22: =Progress!M16 -> 0 | R22: =Progress!N16 -> 0 | S22: =IFERROR(IF(ISBLANK(Q22),"",Q22/O22),0) -> 0 | T22: =IFERROR(IF(ISBLANK(R22),"",R22/O22),0) -> 0 | U22: =Progress!O16 -> 18369 | V22: =Progress!P16 -> 3751 | W22: =IFERROR(IF(ISBLANK(U22),"",U22/O22),0) -> 0.17795608 | X22: =IFERROR(IF(ISBLANK(V22),"",V22/O22),0) -> 0.036339117 | Y22: =IFERROR(X22-W22,"") -> -0.14161696 | Z22: =IFERROR(X22/W22,"") -> 0.20420273
A23: =Progress!A17 -> MV Network | C23: =Progress!C17 -> 1577890 | D23: =Progress!D17 -> 0.047683571 | E23: =Progress!E17 -> 17205.13 | F23: =Progress!F17 -> 0 | H23: =Progress!H17 -> 35478.52 | I23: =Progress!I17 -> 0 | O23: =Progress!K17 -> 37659 | P23: =IF(ISBLANK(O23),"",O23/$O$44) -> 0.058983397 | Q23: =Progress!M17 -> 1036 | R23: =Progress!N17 -> 0 | S23: =IFERROR(IF(ISBLANK(Q23),"",Q23/O23),0) -> 0.027510024 | T23: =IFERROR(IF(ISBLANK(R23),"",R23/O23),0) -> 0 | U23: =Progress!O17 -> 1036 | V23: =Progress!P17 -> 0 | W23: =IFERROR(IF(ISBLANK(U23),"",U23/O23),0) -> 0.027510024 | X23: =IFERROR(IF(ISBLANK(V23),"",V23/O23),0) -> 0 | Y23: =IFERROR(X23-W23,"") -> -0.027510024 | Z23: =IFERROR(X23/W23,"") -> 0
A24: =Progress!A18 -> Earthing System | C24: =Progress!C18 -> 4795 | D24: =Progress!D18 -> 0.0001449041 | E24: =Progress!E57 -> 0 | F24: =Progress!F18 -> 0 | H24: =Progress!H18 -> 0 | I24: =Progress!I18 -> 0 | O24: =Progress!K18 -> 172.8 | P24: =IF(ISBLANK(O24),"",O24/$O$44) -> 0.00027064795 | Q24: =Progress!M18 -> 0 | R24: =Progress!N18 -> 0 | S24: =IFERROR(IF(ISBLANK(Q24),"",Q24/O24),0) -> 0 | T24: =IFERROR(IF(ISBLANK(R24),"",R24/O24),0) -> 0 | U24: =Progress!O18 -> 0 | V24: =Progress!P18 -> 0 | W24: =IFERROR(IF(ISBLANK(U24),"",U24/O24),0) -> 0 | X24: =IFERROR(IF(ISBLANK(V24),"",V24/O24),0) -> 0 | Y24: =IFERROR(X24-W24,"") -> 0 | Z24: =IFERROR(X24/W24,"")
A25: =Progress!A19 -> Street Lighting Network | C25: =Progress!C19 -> 1454545 | D25: =Progress!D19 -> 0.043956106 | F25: =Progress!F19 -> 0 | H25: =Progress!H19 -> 146450.34 | I25: =Progress!I19 -> 6382.5 | O25: =Progress!K19 -> 51050.8 | P25: =IF(ISBLANK(O25),"",O25/$O$44) -> 0.0799583 | Q25: =Progress!M19 -> 9986 | R25: =Progress!N19 -> 0 | S25: =IFERROR(IF(ISBLANK(Q25),"",Q25/O25),0) -> 0.19560908 | T25: =IFERROR(IF(ISBLANK(R25),"",R25/O25),0) -> 0 | U25: =Progress!O19 -> 13326 | V25: =Progress!P19 -> 515 | W25: =IFERROR(IF(ISBLANK(U25),"",U25/O25),0) -> 0.26103411 | X25: =IFERROR(IF(ISBLANK(V25),"",V25/O25),0) -> 0.010087991 | Y25: =IFERROR(X25-W25,"") -> -0.25094612 | Z25: =IFERROR(X25/W25,"") -> 0.038646255
A26: =Progress!A20 -> TELECOMMUNICATIONS WORKS | C26: =Progress!C20 -> 378522 | D26: =Progress!D20 -> 0.011438871 | F26: =Progress!F20 -> 43659.79 | H26: =Progress!H20 -> 65042.96 | I26: =Progress!I20 -> 56246.87 | O26: =Progress!K20 -> 14339.6 | P26: =IF(ISBLANK(O26),"",O26/$O$44) -> 0.022459394 | Q26: =Progress!M20 -> 4008 | R26: =Progress!N20 -> 2429 | S26: =IFERROR(IF(ISBLANK(Q26),"",Q26/O26),0) -> 0.2795057 | T26: =IFERROR(IF(ISBLANK(R26),"",R26/O26),0) -> 0.16939106 | U26: =Progress!O20 -> 4008 | V26: =Progress!P20 -> 3237 | W26: =IFERROR(IF(ISBLANK(U26),"",U26/O26),0) -> 0.2795057 | X26: =IFERROR(IF(ISBLANK(V26),"",V26/O26),0) -> 0.22573851 | Y26: =IFERROR(X26-W26,"") -> -0.05376719 | Z26: =IFERROR(X26/W26,"") -> 0.80763473
A27: =Progress!A21 -> LOW VOLTAGE | C27: =Progress!C21 -> 86942 | D27: =Progress!D21 -> 0.0026273727 | F27: =Progress!F21 -> 0 | I27: =Progress!I21 -> 4926.72 | O27: =Progress!K21 -> 6638.4 | P27: =IF(ISBLANK(O27),"",O27/$O$44) -> 0.010397392 | Q27: =Progress!M21 -> 0 | R27: =Progress!N21 -> 329 | S27: =IFERROR(IF(ISBLANK(Q27),"",Q27/O27),0) -> 0 | T27: =IFERROR(IF(ISBLANK(R27),"",R27/O27),0) -> 0.049560135 | U27: =Progress!O21 -> 0 | V27: =Progress!P21 -> 651 | W27: =IFERROR(IF(ISBLANK(U27),"",U27/O27),0) -> 0 | X27: =IFERROR(IF(ISBLANK(V27),"",V27/O27),0) -> 0.098065799 | Y27: =IFERROR(X27-W27,"") -> 0.098065799 | Z27: =IFERROR(X27/W27,"")
A28: =Progress!A22 -> ROAD - 01 | C28: =Progress!C22 -> 28981 | D28: =Progress!D22 -> 0.00087580096 | E28: =Progress!E43 -> 0 | F28: =Progress!F22 -> 0 | G28: =Progress!G35 -> 0 | H28: =Progress!H35 -> 371500.3 | I28: =Progress!I22 -> 2028.65 | J28: =IFERROR(IF(ISBLANK(G28),"",G28/C28),0) -> 0 | K28: =IFERROR(IF(ISBLANK(I28),"",I28/C28),0) -> 0.06999931 | L28: =IFERROR(IF(ISBLANK(I28),"",I28/C28),0) -> 0.06999931 | M28: =IFERROR(L28-K28,"") -> 0 | N28: =IFERROR(L28/K28,"") -> 1 | O28: =Progress!K22 -> 2072.2 | P28: =IF(ISBLANK(O28),"",O28/$O$44) -> 0.0032455826 | Q28: =Progress!M22 -> 0 | R28: =Progress!N43 -> 0 | S28: =IFERROR(IF(ISBLANK(Q28),"",Q28/O28),0) -> 0 | T28: =IFERROR(IF(ISBLANK(R28),"",R28/O28),0) -> 0 | U28: =Progress!O35 -> 2336 | V28: =Progress!P22 -> 322 | W28: =IFERROR(IF(ISBLANK(U28),"",U28/O28),0) -> 1.1273043 | X28: =IFERROR(IF(ISBLANK(V28),"",V28/O28),0) -> 0.15539041 | Y28: =IFERROR(X28-W28,"") -> -0.97191391 | Z28: =IFERROR(X28/W28,"") -> 0.13784247
A29: =Progress!A23 -> ROAD - 02 | C29: =Progress!C23 -> 57961 | D29: =Progress!D23 -> 0.0017515717 | F29: =Progress!F23 -> 869.42 | O29: =Progress!K23 -> 4566.2 | P29: =IF(ISBLANK(O29),"",O29/$O$44) -> 0.0071518094 | V29: =Progress!P23 -> 328
A30: =Progress!A24 -> PORTABLE WATER | C30: =Progress!C24 -> 379700 | D30: =Progress!D24 -> 0.01147447 | F30: =Progress!F24 -> 210420.04 | O30: =Progress!K24 -> 46755 | P30: =IF(ISBLANK(O30),"",O30/$O$44) -> 0.073230005
A31: =Progress!A25 -> ROAD - 01 | C31: =Progress!C25 -> 189850 | D31: =Progress!D25 -> 0.0057372352 | F31: =Progress!F25 -> -87612.8 | O31: =Progress!K25 -> 20132.1 | P31: =IF(ISBLANK(O31),"",O31/$O$44) -> 0.031531896
A32: =Progress!A26 -> ROAD - 02 | C32: =Progress!C26 -> 189850 | D32: =Progress!D26 -> 0.0057372352 | F32: =Progress!F26 -> 3809.25 | O32: =Progress!K26 -> 26622.9 | P32: =IF(ISBLANK(O32),"",O32/$O$44) -> 0.041698109
A33: =Progress!A27 -> SEWARAGE NETWORK | C33: =Progress!C27 -> 621335 | D33: =Progress!D27 -> 0.01877664 | F33: =Progress!F27 -> 20653.36 | O33: =Progress!K27 -> 19751.7 | P33: =IF(ISBLANK(O33),"",O33/$O$44) -> 0.030936094
A34: =Progress!A28 -> ROAD - 01 | C34: =Progress!C28 -> 372801 | D34: =Progress!D28 -> 0.011265984 | O34: =Progress!K28 -> 12694.5 | P34: =IF(ISBLANK(O34),"",O34/$O$44) -> 0.019882757
A35: =Progress!A29 -> ROAD - 02 | C35: =Progress!C29 -> 248534 | D35: =Progress!D29 -> 0.0075106558 | O35: =Progress!K29 -> 7057.2 | P35: =IF(ISBLANK(O35),"",O35/$O$44) -> 0.011053337
A36: =Progress!A30 -> STORM WATER | C36: =Progress!C30 -> 294040 | D36: =Progress!D30 -> 0.0088858395 | O36: =Progress!K30 -> 748.6 | P36: =IF(ISBLANK(O36),"",O36/$O$44) -> 0.0011724945
A37: =Progress!A31 -> ROAD N... | C37: =Progress!C31 -> 294040 | D37: =Progress!D31 -> 0.0088858395 | O37: =Progress!K31 -> 748.6 | P37: =IF(ISBLANK(O37),"",O37/$O$44) -> 0.0011724945
A38: =Progress!A32 -> Package-3 | C38: =Progress!C32 -> 10588820 | D38: =Progress!D32 -> 0.31999237 | O38: =Progress!K32 -> 133075.3 | P38: =IF(ISBLANK(O38),"",O38/$O$44) -> 0.20842915
A39: =Progress!A33 -> Site Works | C39: =Progress!C33 -> 21090 | D39: =Progress!D33 -> 0.00063733626 | O39: =Progress!K33 -> 1835.5 | P39: =IF(ISBLANK(O39),"",O39/$O$44) -> 0.0028748513
A40: =Progress!A34 -> Earthworks | C40: =Progress!C34 -> 21090 | D40: =Progress!D34 -> 0.00063733626 | O40: =Progress!K34 -> 1835.5 | P40: =IF(ISBLANK(O40),"",O40/$O$44) -> 0.0028748513
A41: =Progress!A35 -> Platform Works | C41: =Progress!C35 -> 6003782 | D41: =Progress!D35 -> 0.18143329 | O41: =Progress!K35 -> 68964.6 | P41: =IF(ISBLANK(O41),"",O41/$O$44) -> 0.10801578
...

Sheet General Information
A1: Weekly Progress Report - Construction Projects | K1: Data Date | L1: 46314
A2: Contract General Information
A3: Project Name | C3: Construction of Passenger Station for SAR Railway Sudair Industrial City
A4: Project ID | C4: SUD1-05-018
A5: Contractor | C5: Technical Dvelopment Co. "TDC"
A6: Consultant | C6: Saudi Arabia Consulting Engineering Company "EGIS"
A7: Stage | C7: Construction
A8: Status | C8: Active
A9: Modon PM | C9: Engr.Zyad Al Shabat
A11: Key Dates
A12: Contract Award Date | C12: 46112
A13: Contract Sign Date | C13: 46112
A14: Site Handover Date | C14: 46119
A15: Original Completion | C15: 46605
A16: Contract Award Date (Hijri) | C16: 10/12/1447
A17: Contract Sign Date (Hijri) | C17: 10/12/1447
A18: Site Handover Date (Hijri) | C18: 11/19/1447
A19: Original Completion (Hijri) | C19: 03/03/1449
A20: Revised Completion Date | C20: 46119
A21: Committed Completion Date | C21: 46605
A22: Forecast Completion | C22: 46605
A23: Variance | C23: =C22-C15 -> 0
A25: Key Project Submittals | C25: Submission Date | D25: Days taken to approve orginal plan from site handover date
A26: Quality Plan submission | C26: 46142 | D26: =C26-C14 -> 23
A27: Quality Plan approval | C27: 46153
A28: Quality Plan Last Update | C28: 46153
A30: Safety Plan submission | C30: 46142 | D30: =C30-C14 -> 23
A31: Safety Plan approval | C31: 46148
A32: Safety Plan Last Update | C32: =C30 -> 46142
A34: Risk Management Plan submission | C34: 46132 | D34: =C34-C14 -> 13
A35: Risk Management Plan approval | C35: 46142
A36: Risk Management Plan Last Update | C36: 46142
A38: Baseline Schedule submission | C38: 46149 | D38: =C38-C14 -> 30
A39: Baseline Schedule approval | C39: 46236
A40: No of Schedule Versions | C40: -
A41: Last Revised Schedule Approval Date | C41: -
A43: BOQ submission | C43: - | D43: -
A44: BOQ approval | C44: -
A45: No of Approved Version of BOQ | C45: -
A47: Execution Plan submission | C47: 46142 | D47: =C47-C14 -> 23
...

Sheet Progress
A1: Project Scope Statement | B1: Construction of Passenger Station for SAR Railway Sudair Industrial City
A4: Earned Value Progress (SAR) | K4: Physical Progress (Effort)
A5: WBS | C5: BOQ Value (SAR) | D5: % Wt. | E5: Weekly (SAR) | H5: To Date (SAR) | K5: Budgeted | L5: % Wt. | M5: Weekly Physical Progress | O5: To Date Physical Progress
E6: Planned | F6: Earned | G6: Original Plan | H6: Planned | I6: Earned | K6: (Manhours) | M6: Planned | N6: Earned | O6: Planned | P6: Earned
A7: Milestones | H7: 0 | I7: 0 | K7: 0 | L7: 0 | O7: 0 | P7: 0
A8: Mobilization | C8: 0 | H8: 0 | I8: 0 | K8: 19154 | L8: 0.029999947 | M8: =O8-O58 -> 0 | N8: =P8-P58 -> 0 | O8: 19793 | P8: 19793
A9: Engineering | C9: 0 | D9: 0 | E9: =H9-H59 -> 0 | F9: =I9-I59 -> 0 | G9: 0 | H9: 0 | I9: 0 | K9: 31923.4 | L9: 0.050000016 | M9: =O9-O59 -> 0 | N9: =P9-P59 -> 0 | O9: 32988 | P9: 31339
A10: Procurement | C10: 0 | D10: 0 | E10: =H10-H60 -> 0 | F10: =I10-I60 -> 0 | G10: 0 | H10: 0 | I10: 0 | K10: 89385.5 | L10: 0.14000001 | M10: =O10-O60 -> 3134 | N10: =P10-P60 -> 4642 | O10: 68347 | P10: 17130
A11: Construction | C11: 33090852 | D11: 1 | E11: =H11-H61 -> 710697.41 | F11: =I11-I61 -> 214091.03 | G11: 0 | H11: 6301807.5 | I11: 7095542 | K11: 478850.8 | L11: 0.74999992 | M11: =O11-O61 -> 8552 | N11: =P11-P61 -> 3430 | O11: 121851 | P11: 98246
A12: Package-1 | C12: 22502032 | D12: 0.68000763 | E12: =H12-H62 -> 613731.64 | F12: =I12-I62 -> 214091.03 | G12: 0 | H12: 5886632.1 | I12: 7095542 | K12: 345775.5 | L12: 0.54157077 | M12: =O12-O62 -> 8143 | N12: =P12-P62 -> 3430 | O12: 109662 | P12: 98246
A13: ROAD WORKS 1 | C13: 17704263 | D13: 0.53501986 | E13: =H13-H63 -> 514154.16 | F13: =I13-I63 -> 111822.59 | G13: 0 | H13: 5366361.2 | I13: 6500573.5 | K13: 168659.6 | L13: 0.26416305 | M13: =O13-O64 -> 15867 | N13: =P13-P63 -> 557 | O13: 73549 | P13: 78905
A14: ROAD - 01 | C14: 10400905 | D14: 0.31431361 | E14: =H14-H64 -> 275854.68 | F14: =I14-I64 -> 111822.59 | G14: 0 | H14: 3150987.4 | I14: 4140066.2 | K14: 96629.6 | L14: 0.15134608 | M14: =O14-O64 -> 1058 | N14: =P14-P64 -> 557 | O14: 58740 | P14: 62660
A15: ROAD - 02 | C15: 7303358 | D15: 0.22070625 | E15: =H15-H65 -> 238299.48 | F15: =I15-I65 -> 0 | H15: 2215373.7 | I15: 2360507.3 | K15: 72030.1 | L15: 0.11281712 | M15: =O15-O65 -> 1164 | N15: =P15-P65 -> 0 | O15: 14810 | P15: 16245
A16: ELECTRICAL WORKS | C16: 3415753 | D16: 0.10322348 | E16: =H16-H66 -> 62394.6 | F16: =I16-I66 -> 43659.79 | H16: 246971.83 | I16: 62629.37 | K16: 103222.1 | L16: 0.16167158 | N16: =Q16-Q65 -> 0 | O16: 18369 | P16: 3751
A17: MV Network | C17: 1577890 | D17: 0.047683571 | E17: =H17-H67 -> 17205.13 | F17: =I17-I67 -> 0 | H17: 35478.52 | I17: 0 | K17: 37659 | L17: 0.058983397 | M17: =O17-O68 -> 1036 | N17: =P17-P68 -> 0 | O17: 1036 | P17: 0
A18: Earthing System | C18: 4795 | D18: 0.0001449041 | E18: =H18-H68 -> 0 | F18: =I18-I67 -> 0 | H18: 0 | I18: 0 | K18: 172.8 | L18: 0.00027064795 | M18: =O18-O68 -> 0 | N18: =P18-P68 -> 0 | O18: 0 | P18: 0
A19: Street Lighting Network | C19: 1454545 | D19: 0.043956106 | E19: =H19-H69 -> 30727.34 | F19: =I19-I69 -> 0 | H19: 146450.34 | I19: 6382.5 | K19: 51050.8 | L19: 0.0799583 | M19: =O19-O70 -> 9986 | N19: =P19-P69 -> 0 | O19: 13326 | P19: 515
A20: TELECOMMUNICATIONS WORKS | C20: 378522 | D20: 0.011438871 | E20: =H20-H70 -> 14462.12 | F20: =I20-I70 -> 43659.79 | H20: 65042.96 | I20: 56246.87 | K20: 14339.6 | L20: 0.022459394 | M20: =O20-O71 -> 4008 | N20: =P20-P70 -> 2429 | O20: 4008 | P20: 3237
A21: LOW VOLTAGE | C21: 86942 | D21: 0.0026273727 | E21: =H21-H71 -> 0 | F21: =I21-I71 -> 0 | H21: 0 | I21: 4926.72 | K21: 6638.4 | L21: 0.010397392 | M21: =O21-O72 -> 0 | N21: =P21-P72 -> 329 | O21: 0 | P21: 651
A22: ROAD - 01 | C22: 28981 | D22: 0.00087580096 | E22: =H22-H72 -> 0 | F22: =I22-I72 -> 0 | H22: 0 | I22: 2028.65 | K22: 2072.2 | L22: 0.0032455826 | M22: =O22-O73 -> 0 | N22: =P22-P72 -> 0 | O22: 0 | P22: 322
A23: ROAD - 02 | C23: 57961 | D23: 0.0017515717 | E23: =H23-H73 -> 0 | F23: =I23-I72 -> 869.42 | H23: 0 | I23: 2898.07 | K23: 4566.2 | L23: 0.0071518094 | M23: =O23-O74 -> -9146 | N23: =P23-P73 -> 0 | O23: 0 | P23: 328
A24: PORTABLE WATER | C24: 379700 | D24: 0.01147447 | E24: =H24-H74 -> 11904.6 | F24: =I24-I73 -> 210420.04 | H24: 66242.45 | I24: 213318.11 | K24: 46755 | L24: 0.073230005 | M24: =O24-O75 -> 7499 | N24: =P24-P75 -> 4879 | O24: 11285 | P24: 12074
A25: ROAD - 01 | C25: 189850 | D25: 0.0057372352 | E25: =H25-H75 -> 5695.33 | F25: =I25-I74 -> -87612.8 | H25: 30835.92 | I25: 121896.06 | K25: 20132.1 | L25: 0.031531896 | M25: =O25-O76 -> -614 | N25: =P25-P76 -> 2412 | O25: 4746 | P25: 7195
A26: ROAD - 02 | C26: 189850 | D26: 0.0057372352 | E26: =H26-H76 -> 6209.26 | F26: =I26-I76 -> 3809.25 | H26: 35406.53 | I26: 91422.05 | K26: 26622.9 | L26: 0.041698109 | M26: =O26-O76 -> 1179 | N26: =P26-P76 -> 96 | O26: 6539 | P26: 4879
A27: SEWARAGE NETWORK | C27: 621335 | D27: 0.01877664 | E27: =H27-H76 -> 98048.47 | F27: =I27-I76 -> 20653.36 | H27: 127245.74 | I27: 108266.16 | K27: 19751.7 | L27: 0.030936094 | M27: =O27-O78 -> 2570 | N27: =P27-P77 -> 312 | O27: 6304 | P27: 2638
A28: ROAD - 01 | C28: 372801 | D28: 0.011265984 | E28: =H28-H77 -> -32403.53 | F28: =I28-I77 -> 0 | H28: 79365.26 | I28: 90221.8 | K28: 12694.5 | L28: 0.019882757 | M28: =O28-O79 -> 2872 | N28: =P28-P79 -> 1863 | O28: 4447 | P28: 2226
A29: ROAD - 02 | C29: 248534 | D29: 0.0075106558 | E29: =H29-H78 -> -23284.72 | F29: =I29-I79 -> 2122.86 | H29: 47880.48 | I29: 18044.36 | K29: 7057.2 | L29: 0.011053337 | M29: =O29-O80 -> 1723 | N29: =P29-P79 -> 49 | O29: 1857 | P29: 412
A30: STORM WATER | C30: 294040 | D30: 0.0088858395 | E30: =H30-H79 -> 39207.33 | F30: =I30-I79 -> 189906.67 | H30: 79810.92 | I30: 205828.17 | K30: 748.6 | L30: 0.0011724945 | M30: =O30-O81 -> 22 | N30: =P30-P80 -> 38 | O30: 156 | P30: 228
A31: ROAD N... | C31: 294040 | D31: 0.0088858395 | E31: =H31-H80 -> 9801.34 | F31: =I31-I80 -> 36755.03 | H31: 79810.92 | I31: 205828.17 | K31: 748.6 | L31: 0.0011724945 | M31: =O31-O81 -> 22 | N31: =P31-P82 -> 228 | O31: 156 | P31: 228
A32: Package-3 | C32: 10588820 | D32: 0.31999237 | E32: =H32-H82 -> 96965.76 | F32: =I32-I82 -> 0 | H32: 415175.34 | I32: 0 | K32: 133075.3 | L32: 0.20842915 | M32: =O32-O82 -> 410 | N32: =P32-P83 -> 0 | O32: 12190 | P32: 0
A33: Site Works | C33: 21090 | D33: 0.00063733626 | E33: =H33-H82 -> -297119.56 | F33: =I33-I82 -> 0 | H33: 21090.02 | I33: 0 | K33: 1835.5 | L33: 0.0028748513 | M33: =O33-O83 -> 0 | N33: =P33-P84 -> 0 | O33: 9506 | P33: 0
A34: Earthworks | C34: 21090 | D34: 0.00063733626 | E34: =H34-H83 -> 0 | F34: =I34-I83 -> 0 | H34: 21090.02 | I34: 0 | K34: 1835.5 | L34: 0.0028748513 | M34: =O34-O84 -> 0 | N34: =P34-P85 -> 0 | O34: 9506 | P34: 0
A35: Platform Works | C35: 6003782 | D35: 0.18143329 | E35: =H35-H85 -> 84562.57 | F35: =I35-I84 -> 0 | G35: 0 | H35: 371500.3 | I35: 0 | K35: 68964.6 | L35: 0.10801578 | M35: =O35-O86 -> 238 | N35: =P35-P86 -> 0 | O35: 2336 | P35: 0
A36: Platform Substructure | C36: 5037344 | D36: 0.15222769 | E36: =H36-H85 -> 84562.57 | F36: =I36-I85 -> 0 | G36: 0 | H36: 371500.3 | I36: 0 | K36: 47410.5 | L36: 0.074256681 | M36: =O36-O87 -> 2336 | N36: =P36-P87 -> 0 | O36: 2336 | P36: 0
A37: Finishes & Architectural Works | C37: 966437 | D37: 0.029205564 | E37: =H37-H87 -> 0 | F37: =I37-I86 -> 0 | H37: 0 | I37: 0 | K37: 21151.7 | L37: 0.033128844 | M37: =O37-O88 -> 0 | N37: =P37-P88 -> 0 | O37: 0 | P37: 0
A38: Platform Electrical Works | C38: 0 | D38: 0 | H38: 0 | I38: 0 | K38: 402.4 | L38: 0.00063025888 | O38: 0 | P38: 0
A39: Canopy works | C39: 3863605 | D39: 0.1167575 | H39: 22585.02 | I39: 0 | K39: 33380.9 | L39: 0.052282825 | O39: 348 | P39: 0
A40: Civil and Architectural Works | C40: 166440 | D40: 0.0050297889 | H40: 11200.01 | I40: 0 | K40: 1830.7 | L40: 0.0028673333 | O40: 228 | P40: 0
A41: Metals | C41: 3697165 | D41: 0.11172771 | H41: 11385.01 | I41: 0 | K41: 31550.3 | L41: 0.049415648 | O41: 120 | P41: 0
A42: Electrical Works | C42: 700343 | D42: 0.021164248 | H42: 0 | I42: 0 | K42: 28894.3 | L42: 0.045255689 | O42: 0 | P42: 0
...

Sheet Weekly Photos
B1: WEEKLY PROGRESS PHOTOS | V1: ='[36]General Information'!K1 -> Data Date | W1: ='General Information'!L1 -> 46314
B2: Asphalt base course first layer 8 cm at Road 1 | L2: Asphalt base course first layer 8 cm at Road 1
B40: Aggregate Base course layer at Road 1 | L40: Aggregate Base course layer at Road 1
B59: Grading for second layer of subgrade at Road no.1 From st 00+650 to 00+950 | L59: Grading for second layer of subgrade at Road no.1 From st 00+650 to 00+950

Sheet Quality-Stat
A1: Quality -Stat
A2: Quality Reports
A3: Item | C3: Issued | D3: Closed | E3: Pending | F3: Avg. Closing (Days) | G3: Pending
G4: 0-10 Days | H4: 11-20 Days | I4: 21-30 Days | J4: 31-60 Days | K4: > 60 Days
A6: Non Conforomance Report (NCR) | C6: 4 | D6: 4 | E6: =C6-D6 -> 0 | H6: - | I6: - | J6: - | K6: -
A7: Site Instruction (SI) | C7: 0 | D7: 0 | E7: =C7-D7 -> 0 | G7: - | H7: 0 | I7: 0 | J7: 0 | K7: 0
A8: Material Inspection Report (MIR) | C8: 15 | D8: 15 | E8: =C8-D8 -> 0 | G8: =C8-D8 -> 0 | H8: 0 | I8: 0 | J8: 0 | K8: 0
A9: Field Inspection Request (FIR) | C9: 152 | D9: 143 | E9: =C9-D9 -> 9 | G9: =C9-D9 -> 9 | H9: 0 | I9: 0 | J9: 0 | K9: 0
A11: Shop Drawings
A12: Item Per WBS | D12: Total | E12: Total Drawings Submitted | J12: Remaining Drawings | K12: Pending | L12: Total Submittals
E13: A | F13: B | G13: C | H13: D | I13: Processed(A+B+C+D) | J13: with Designer | K13: Submittals With Consultant
A14: Road work | D14: 90 | E14: 80 | F14: 10 | G14: 0 | H14: 0 | I14: =E14+F14+G14+H14 -> 90 | J14: 0 | K14: 0 | L14: =I14 -> 90
A15: wet network(sewer,potable,Storm) | D15: 47 | E15: 13 | F15: 34 | G15: 0 | H15: 0 | I15: =E15+F15+G15+H15 -> 47 | J15: =D15-I15 -> 0 | K15: 0 | L15: =I15 -> 47
A16: Telecom | D16: 15 | E16: 8 | F16: 7 | G16: 0 | H16: 0 | I16: =E16+F16+G16+H16 -> 15 | J16: 0 | K16: 0 | L16: =I16 -> 15
A17: Lighting | C17: Mechanical | D17: 28 | E17: 8 | F17: 20 | G17: 0 | H17: 0 | I17: =E17+F17+G17+H17 -> 28 | J17: 0 | K17: 0 | L17: =I17 -> 28
A18: Electrical | C18: Electrical | D18: 24 | E18: 5 | F18: 19 | G18: 0 | H18: 0 | I18: =E18+F18+G18+H18 -> 24 | J18: 0 | K18: 0 | L18: =I18 -> 24
A19: TOTAL | D19: =SUM(D14:D18) -> 204 | E19: =SUM(E14:E18) -> 114 | F19: =SUM(F14:F18) -> 90 | G19: =SUM(G14:G18) -> 0 | H19: =SUM(H14:H18) -> 0 | I19: =SUM(I14:I18) -> 204 | J19: =SUM(J14:J18) -> 0 | K19: =SUM(K14:K18) -> 0 | L19: =SUM(L14:L18) -> 204
A22: Material Approval
A23: Item Per WBS | D23: Total | E23: Total Materials Submitted | J23: Remaining to approve | K23: Pending | L23: Total Submittals
E24: A | F24: B | G24: C | H24: D | I24: Processed(A+B+C+D) | J24: with Designer | K24: Submittals With Consultant
A25: Civil /Structural /Architectural | D25: 20 | E25: 0 | F25: 18 | G25: 1 | H25: 0 | I25: =E25+F25+G25+H25 -> 19 | J25: 0 | K25: 1 | L25: =I25+J25+K25 -> 20
A26: Electrical | C26: Mechanical | D26: 16 | E26: 1 | F26: 13 | G26: 2 | H26: 0 | I26: 16 | J26: 0 | K26: 0 | L26: =I26+J26+K26 -> 16
A27: Mechanical/STR | C27: Electrical | D27: 7 | E27: 0 | F27: 7 | G27: 0 | H27: 0 | I27: =E27+F27+G27+H27 -> 7 | J27: =D27-I27 -> 0 | K27: 0 | L27: =I27+J27+K27 -> 7
A28: TOTAL | D28: =SUM(D23:D27) -> 43 | E28: =SUM(E25:E27) -> 1 | F28: =SUM(F25:F27) -> 38 | G28: =SUM(G25:G27) -> 3 | H28: =SUM(H25:H27) -> 0 | I28: =SUM(I25:I27) -> 42 | J28: 0 | K28: =SUM(K25:K27) -> 1 | L28: =SUM(L25:L27) -> 43
A30: Procurement Summary
A31: Item Per WBS | D31: Total Materials | E31: Total Number of P.O. | F31: Actual P.O. To Date | G31: Remaining P.O | H31: Actual Material on Site | I31: Remaining Materials | J31: Material Delivery Completion (Date)
E32: A | F32: B | G32: C | H32: D | I32: Processed
A33: Civil /Structural /Architectural | D33: 3 | E33: 2 | F33: 2 | G33: 1 | H33: 0 | I33: =D33-H33 -> 3 | J33: -
A34: Electrical | C34: Electrical | D34: 18 | E34: 15 | F34: 15 | G34: 3 | H34: 6 | I34: 6 | J34: -
A35: Mechanical | C35: Electrical | D35: 6 | E35: 5 | F35: 5 | G35: 1 | H35: 3 | I35: 3 | J35: -
A36: TOTAL | D36: =SUM(D33:D35) -> 27 | E36: =SUM(E33:E35) -> 22 | F36: =SUM(F33:F35) -> 22 | G36: =SUM(G33:G35) -> 5 | H36: =SUM(H33:H35) -> 9 | I36: =SUM(I33:I35) -> 12
A38: Consultant Quality Inspections / Observations (Weekly Basis) | I38: Overall Average | J38: - | L38: Average Closing | M38: -
A39: Week Number | B39: Date of Audit | C39: Date Issued | D39: Numbers Of Comments | E39: Quality Score | F39: Date Closed | G39: Closure Duration | I39: This Week Score | J39: - | L39: Average Number of Comments Per Audit | M39: -

Sheet Quality.
B2: QC OBSERVATIONS CHECKLIST
BB4: 45377
B6: Project No. | E6: SUD1-05-018 | K6: OBS No. | U6: Inspection Day: | X6: ='General Information'!L1 -> 46314
B8: Project | E8: Construction of Passenger Station for SAR Railway Sudair Industrial City | O8: Contractor: Consultant: | U8: Technical Development Company Egis Engineering cunsultancy
B10: 4 | D10: Excellent | G10: Quality Management System is being practiced and applies to MODON System | Z10: 90 - 100 | AB10: QC Overall Score | AC10: =Q49 -> 0.88724138 | AN10: =SUM(Z10:Z13) -> 0 | AO10: 100 | AP10: 0.22883295
B11: 3 | D11: Good | G11: Evidence of compliance with plans and procedures. | Z11: 80 - 89 | AN11: =SUM(Y10:Y14) -> 0 | AO11: 89 | AP11: 0.20366133
B12: 2 | D12: Average | G12: Indication level of compliance with standards but there is room for improvement | Z12: 70 - 79 | AO12: 79 | AP12: 0.18077803
B13: 1 | D13: Improve | G13: Quality and Control is NOT being managed effectively. Needs Improvement | Z13: ≤ 69 | AO13: 69 | AP13: 0.15789474
B14: 0 | D14: N/A | G14: Item was not applicable or this item was not reviewed during the inspection. | Z14: Zero | AO14: 100 | AP14: 0.22883295
B16: No. | C16: Topic | K16: E (4) | L16: G (3) | M16: A (2) | N16: I (1) | O16: N/A (0) | Q16: No. | R16: Topic | Z16: E (4) | AA16: G (3) | AB16: A (2) | AC16: I (1) | AD16: N/A (0) | AO16: =SUM(AO10:AO15) -> 437
K17: 1 | L17: 0.89 | M17: 0.79 | N17: 0.69 | O17: 1 | Z17: 1 | AA17: 0.89 | AB17: 0.79 | AC17: 0.69 | AD17: 1 | AF17: =SUM(AF18:AG46)/COUNT(AF18:AG46) -> 0.88724138
B18: 1 | C18: Control of Access to Site/Office | L18: 1 | Q18: 30 | R18: QC of Excavation | Z18: 0 | AA18: 1 | AD18: 0 | AF18: =SUMPRODUCT($K$17:$O$17,K18:O18) -> 0.89 | AG18: =SUMPRODUCT($Z$17:$AD$17,Z18:AD18) -> 0.89 | AV18: Item Count | AW18: Score | AX18: Distributtion
B19: 2 | C19: Document Control Administration | L19: 1 | Q19: 31 | R19: QC of Roads/Round about | AA19: 1 | AB19: 0 | AF19: =SUMPRODUCT($K$17:$O$17,K19:O19) -> 0.89 | AG19: =SUMPRODUCT($Z$17:$AD$17,Z19:AD19) -> 0.89 | AX19: Overall | AY19: Relevant
B20: 3 | C20: Project Documents and Progress | L20: 1 | Q20: 32 | R20: QC of Interlock & Curbstone | AA20: 1 | AB20: 0 | AF20: =SUMPRODUCT($K$17:$O$17,K20:O20) -> 0.89 | AG20: =SUMPRODUCT($Z$17:$AD$17,Z20:AD20) -> 0.89 | AM20: 4 | AN20: =58 -> 58 | AO20: counts | AQ20: 4 | AR20: Excellent | AV20: =SUM(Z18:Z46,K18:K46) -> 1 | AW20: =AQ20*AV20 -> 4 | AX20: =AV20/$AV$25 -> 0.01754386 | AY20: =AV20/SUM($AV$20:$AV$23) -> 0.028571429
B21: 4 | C21: Contractor's Quality Plan/CM (Updated and Reviewed) | K21: 0 | L21: 1 | Q21: 33 | R21: Layers/Backfilling Sampling | Z21: 0 | AA21: 1 | AB21: 0 | AD21: 0 | AF21: =SUMPRODUCT($K$17:$O$17,K21:O21) -> 0.89 | AG21: =SUMPRODUCT($Z$17:$AD$17,Z21:AD21) -> 0.89 | AM21: 3 | AN21: =58 -> 58 | AO21: counts | AQ21: 3 | AR21: Good | AV21: =SUM(L18:L46,AA18:AA46) -> 23 | AW21: =AQ21*AV21 -> 69 | AX21: =AV21/$AV$25 -> 0.40350877 | AY21: =AV21/SUM($AV$20:$AV$23) -> 0.65714286
B22: 5 | C22: MS Log and Paperwork | L22: 1 | M22: 0 | Q22: 34 | R22: Pump Stations Units | AC22: 0 | AD22: 1 | AF22: =SUMPRODUCT($K$17:$O$17,K22:O22) -> 0.89 | AG22: =SUMPRODUCT($Z$17:$AD$17,Z22:AD22) -> 1 | AM22: 2 | AN22: =58 -> 58 | AO22: counts | AQ22: 2 | AR22: Average | AV22: =SUM(M18:M46,AB18:AB46) -> 4 | AW22: =AQ22*AV22 -> 8 | AX22: =AV22/$AV$25 -> 0.070175439 | AY22: =AV22/SUM($AV$20:$AV$23) -> 0.11428571
B23: 6 | C23: RFI, FIR, & MIR Procedure | L23: 1 | Q23: 35 | R23: Quality of Form Work | AA23: 0 | AC23: 0 | AD23: 0 | AF23: =SUMPRODUCT($K$17:$O$17,K23:O23) -> 0.89 | AG23: =SUMPRODUCT($Z$17:$AD$17,Z23:AD23) -> 0 | AM23: 1 | AN23: =58 -> 58 | AO23: counts | AQ23: 1 | AR23: Improve | AV23: =SUM(N18:N46,AC18:AC46) -> 7 | AW23: =AQ23*AV23 -> 7 | AX23: =AV23/$AV$25 -> 0.12280702 | AY23: =AV23/SUM($AV$20:$AV$23) -> 0.2
B24: 7 | C24: RFI, FIR, & MIR Inventory system | L24: 1 | Q24: 36 | R24: Design Change List | AD24: 1 | AF24: =SUMPRODUCT($K$17:$O$17,K24:O24) -> 0.89 | AG24: =SUMPRODUCT($Z$17:$AD$17,Z24:AD24) -> 1 | AM24: 0 | AN24: =58 -> 58 | AO24: counts | AQ24: 0 | AR24: N/A | AV24: =SUM(O18:O46,AD18:AD46) -> 22 | AW24: =AQ24*AV24 -> 0 | AX24: =AV24/$AV$25 -> 0.38596491 | AY24: -
B25: 8 | C25: NCRs Control & Procedure | L25: 1 | M25: 0 | Q25: 37 | R25: Quality of Concrete Placing | AA25: 0 | AB25: 0 | AC25: 0 | AD25: 1 | AF25: =SUMPRODUCT($K$17:$O$17,K25:O25) -> 0.89 | AG25: =SUMPRODUCT($Z$17:$AD$17,Z25:AD25) -> 1 | AR25: Total | AV25: =SUM(AV20:AV24) -> 57 | AW25: =SUM(AW20:AW24) -> 88 | AX25: =SUM(AX20:AX24) -> 1 | AY25: =SUM(AY20:AY24) -> 1
B26: 9 | C26: NCR Log | L26: 1 | Q26: 38 | R26: Concrete Surface Finishing | AA26: 0 | AB26: 0 | AC26: 0 | AD26: 1 | AF26: =SUMPRODUCT($K$17:$O$17,K26:O26) -> 0.89 | AG26: =SUMPRODUCT($Z$17:$AD$17,Z26:AD26) -> 1
B27: 10 | C27: MODON Standard* | K27: 0 | M27: 1 | Q27: 39 | R27: Pedestals/Columns/Beams Alignment | AA27: 0 | AD27: 1 | AF27: =SUMPRODUCT($K$17:$O$17,K27:O27) -> 0.79 | AG27: =SUMPRODUCT($Z$17:$AD$17,Z27:AD27) -> 1 | AV27: Maz Score Available: | AW27: =SUM(AV20:AV23)*AQ20 -> 140 | AX27: <- Excludes N/A items
B28: 11 | C28: Project Risk Plan/Management* | M28: 0 | N28: 1 | Q28: 40 | R28: Siporex Lifting & Unloading | AD28: 1 | AF28: =SUMPRODUCT($K$17:$O$17,K28:O28) -> 0.69 | AG28: =SUMPRODUCT($Z$17:$AD$17,Z28:AD28) -> 1
B29: 12 | C29: Monthly Quality Reports* | L29: 0 | M29: 0 | N29: 1 | O29: 0 | Q29: 41 | R29: Siporex Quality Pre-installation | AD29: 1 | AF29: =SUMPRODUCT($K$17:$O$17,K29:O29) -> 0.69 | AG29: =SUMPRODUCT($Z$17:$AD$17,Z29:AD29) -> 1
B30: 13 | C30: ITP | L30: 0 | M30: 1 | O30: 0 | Q30: 42 | R30: Siporex Finishing Quality | AD30: 1 | AF30: =SUMPRODUCT($K$17:$O$17,K30:O30) -> 0.79 | AG30: =SUMPRODUCT($Z$17:$AD$17,Z30:AD30) -> 1 | AR30: Total Score | AW30: Percentage (%)
B31: 14 | C31: MODON Weekly Report | L31: 0 | N31: 1 | Q31: 43 | R31: Roads / Parking Markings | AA31: 1 | AD31: 0 | AF31: =SUMPRODUCT($K$17:$O$17,K31:O31) -> 0.69 | AG31: =SUMPRODUCT($Z$17:$AD$17,Z31:AD31) -> 0.89 | AN31: =MAX(AN20:AN24) -> 58 | AR31: =AW25 -> 88 | AW31: =SUM(100/AR33*AR31) -> 62.857143 | AY31: %
B32: 15 | C32: Design Change Official Paperwork* | N32: 0 | O32: 1 | Q32: 44 | R32: QC of Finishing Outdoors | AC32: 0 | AD32: 1 | AF32: =SUMPRODUCT($K$17:$O$17,K32:O32) -> 1 | AG32: =SUMPRODUCT($Z$17:$AD$17,Z32:AD32) -> 1 | AR32: Max Score Available | BP32: 31
B33: 16 | C33: Design Change was Applied* | O33: 1 | Q33: 45 | R33: Quality of Finishing Indoors | AD33: 1 | AF33: =SUMPRODUCT($K$17:$O$17,K33:O33) -> 1 | AG33: =SUMPRODUCT($Z$17:$AD$17,Z33:AD33) -> 1 | AR33: =AW27 -> 140 | BP33: 32
B34: 17 | C34: Material List | K34: 0 | L34: 1 | O34: 0 | Q34: 46 | R34: Stairs Quality | AD34: 1 | AF34: =SUMPRODUCT($K$17:$O$17,K34:O34) -> 0.89 | AG34: =SUMPRODUCT($Z$17:$AD$17,Z34:AD34) -> 1 | BP34: 33
B35: 18 | C35: Pending Material Status | L35: 1 | O35: 0 | Q35: 47 | R35: Tanks Method Statement Work | AB35: 0 | AC35: 0 | AD35: 1 | AF35: =SUMPRODUCT($K$17:$O$17,K35:O35) -> 0.89 | AG35: =SUMPRODUCT($Z$17:$AD$17,Z35:AD35) -> 1 | BP35: 34
B36: 19 | C36: Lifting Plan* | K36: 0 | L36: 0 | N36: 1 | O36: 0 | Q36: 48 | R36: Electric Rooms | AD36: 1 | AF36: =SUMPRODUCT($K$17:$O$17,K36:O36) -> 0.69 | AG36: =SUMPRODUCT($Z$17:$AD$17,Z36:AD36) -> 1 | BP36: 35
B37: 20 | C37: DWG Log | M37: 0 | N37: 1 | Q37: 49 | R37: QC of MCC/ATS Plant Units | AD37: 1 | AF37: =SUMPRODUCT($K$17:$O$17,K37:O37) -> 0.69 | AG37: =SUMPRODUCT($Z$17:$AD$17,Z37:AD37) -> 1 | BP37: 36
B38: 21 | C38: Invoice Status | K38: 0 | L38: 0 | N38: 1 | Q38: 50 | R38: Qualified Subcontractor | AA38: 1 | AD38: 0 | AF38: =SUMPRODUCT($K$17:$O$17,K38:O38) -> 0.69 | AG38: =SUMPRODUCT($Z$17:$AD$17,Z38:AD38) -> 0.89 | BP38: 37
B39: 22 | C39: Site Handover Letter | K39: 1 | O39: 0 | Q39: 51 | R39: Scaffold/Ladders/Slope/Bridge Compliance | AD39: 1 | AF39: =SUMPRODUCT($K$17:$O$17,K39:O39) -> 1 | AG39: =SUMPRODUCT($Z$17:$AD$17,Z39:AD39) -> 1 | BP39: 38
B40: 23 | C40: Material Testing Results & Certification | L40: 0 | N40: 1 | Q40: 52 | R40: Protection Applied to Completed Work | AA40: 0 | AC40: 0 | AD40: 1 | AF40: =SUMPRODUCT($K$17:$O$17,K40:O40) -> 0.69 | AG40: =SUMPRODUCT($Z$17:$AD$17,Z40:AD40) -> 1
B41: 24 | C41: As Build Drawings Status* | N41: 0 | O41: 1 | Q41: 53 | R41: Storage Management in/out Control | AA41: 0 | AD41: 1 | AF41: =SUMPRODUCT($K$17:$O$17,K41:O41) -> 1 | AG41: =SUMPRODUCT($Z$17:$AD$17,Z41:AD41) -> 1
B42: 25 | C42: Calibrated Lab Tools & Equipment | L42: 1 | O42: 0 | Q42: 54 | R42: Material Control | AA42: 1 | AD42: 0 | AF42: =SUMPRODUCT($K$17:$O$17,K42:O42) -> 0.89 | AG42: =SUMPRODUCT($Z$17:$AD$17,Z42:AD42) -> 0.89
B43: 26 | C43: Storage Inventory System | L43: 1 | O43: 0 | Q43: 55 | R43: Manholes Storing and Quality | AD43: 1 | AF43: =SUMPRODUCT($K$17:$O$17,K43:O43) -> 0.89 | AG43: =SUMPRODUCT($Z$17:$AD$17,Z43:AD43) -> 1
B44: 27 | C44: Logistics Plan | L44: 1 | O44: 0 | Q44: 56 | R44: Reinforced Steel Quality | AB44: 0 | AC44: 0 | AD44: 1 | AF44: =SUMPRODUCT($K$17:$O$17,K44:O44) -> 0.89 | AG44: =SUMPRODUCT($Z$17:$AD$17,Z44:AD44) -> 1
B45: 28 | C45: Project Progress Planview | M45: 1 | O45: 0 | Q45: 57 | R45: Safety Overview | Z45: 0 | AA45: 1 | AF45: =SUMPRODUCT($K$17:$O$17,K45:O45) -> 0.79 | AG45: =SUMPRODUCT($Z$17:$AD$17,Z45:AD45) -> 0.89
B46: 29 | C46: Sufficient Number of QC Inspectors | L46: 0 | M46: 1 | O46: 0 | Q46: 58 | R46: Waste Management Control | Z46: 0 | AA46: 1 | AB46: 0 | AD46: 0 | AF46: =SUMPRODUCT($K$17:$O$17,K46:O46) -> 0.79 | AG46: =SUMPRODUCT($Z$17:$AD$17,Z46:AD46) -> 0.89
...

Sheet HSE-Stat
A1: Safety Statistics
A3: Category | B3: Item | D3: This Week | E3: This Month | F3: Year to Date | G3: Cumulative
A4: Category | B4: Total Hours Worked | D4: 4280 | E4: 9540 | F4: 77050 | G4: 77050
B5: Safe Hours Worked | D5: 4280 | E5: 9540 | F5: 77050 | G5: 77050
B6: No.of Internal Training | D6: 1 | E6: 3 | F6: 22 | G6: 22
B7: No.of Internal Audit
B8: No. of Toolbox Talks | D8: 1 | E8: 3 | F8: 20 | G8: 20
B9: Safety Awards/Incentives
I10: Category | J10: Item | L10: This Week | M10: This Month | N10: Year to Date | O10: Cumulative
A12: Consultant Safety Inspection (Weekly Basis) | I12: Overall Average | J12: 0.8333
A13: Week Number | B13: Date of Audit | C13: Date Issued | D13: Numbers Of Comments | E13: Overall Score | F13: Date Closed | G13: Closure Duration | I13: This Week Score | J13: =E30 -> 0.83333333
A14: Week-1 | D14: 0 | E14: 0.76 | G14: 0
A15: Week-2 | D15: 0 | E15: 0.76 | G15: 0
A16: Week-3 | D16: 0 | E16: =HSE.!AE6 -> 0.83333333 | G16: 0
A17: Week-4 | D17: 0 | E17: 0.77 | G17: 0
A18: Week-5 | D18: 0 | E18: =HSE.!AE6 -> 0.83333333 | G18: 0
A19: Week-6 | D19: 0 | E19: =HSE.!AE6 -> 0.83333333 | G19: 0
A20: Week-7 | D20: 0 | E20: =E19 -> 0.83333333 | G20: 0
A21: Week-8 | D21: 0 | E21: =E20 -> 0.83333333 | G21: 0
A22: Week-9 | D22: 0 | E22: =E21 -> 0.83333333 | G22: 0
A23: Week-10 | B23: 46251 | C23: 46251 | D23: 0 | E23: =E22 -> 0.83333333 | F23: 46251 | G23: 0
A24: Week-11 | B24: 46258 | C24: 46258 | D24: 0 | E24: =E23 -> 0.83333333 | F24: 46258 | G24: 0
A25: Week-12 | B25: 46265 | C25: 46265 | D25: 0 | E25: =E24 -> 0.83333333 | F25: 46265 | G25: 0
A26: Week-13 | B26: 46272 | C26: 46272 | D26: 0 | E26: =E25 -> 0.83333333 | F26: 46272 | G26: 0
A27: Week-14 | B27: 46279 | C27: 46279 | D27: 0 | E27: =E26 -> 0.83333333 | F27: 46279 | G27: 0
A28: Week-15 | B28: 46286 | C28: 46286 | D28: 0 | E28: =E27 -> 0.83333333 | F28: 46286 | G28: 0
A29: Week-16 | B29: 46293 | C29: 46293 | D29: 0 | E29: =E28 -> 0.83333333 | F29: 46293 | G29: 0
A30: Week-17 | B30: 46300 | C30: 46300 | D30: 0 | E30: =E29 -> 0.83333333 | F30: 46300 | G30: 0
A31: Week-18 | B31: 46307 | C31: 46307 | D31: 0 | E31: 0.83 | F31: 46307 | G31: 0
A32: Week-19 | B32: 46314 | C32: 46314 | D32: 0 | E32: 0.83 | F32: 46314 | G32: 0
A33: Week-20 | D33: 0 | E33: 0 | G33: 0
A34: Week-21 | D34: 0 | E34: 0 | G34: 0
A35: Week-22 | D35: 0 | E35: 0 | G35: 0
A36: Week-23 | D36: 0 | E36: 0 | G36: 0
A37: Week-24 | D37: 0 | E37: 0 | G37: 0
A38: Week-25 | D38: 0 | E38: 0 | G38: 0
A39: Week-26 | D39: 0 | E39: 0 | G39: 0
A40: Week-27 | D40: 0 | E40: 0 | G40: 0
A41: Week-28 | D41: 0 | E41: 0 | G41: 0
A42: Week-29 | D42: 0 | E42: 0 | G42: 0

Sheet HSE.
B1: MODON HSE Site Inspection Report
B2: Date | E2: ='General Information'!L1 -> 46314 | L2: Inspected By: | T2: Engr Ayman Sabry
B4: Project ID. | E4: SUD1-02-011 | L4: Report No. | W4: MODON PM Name | Y4: Engr.Ziyad Al Shabbat
B6: Project Name: | E6: Construction of Passenger Station for SAR Railway Sudair Industrial City | L6: Contractor: | R6: TECHNICAL DEVELOPMENT CONTRACTING CO. | X6: Safety Performance | AA6: =IF(W29>0,3,IF(L29>6,2,IF(D29>0,2,1)*1)*1) -> 2 | AE6: =(((COUNTIF(L13:Q25,"1")+COUNTIF(AC13:AH25,"1"))*AR13)+(COUNTIF(L13:Q25,"2")+COUNTIF(AC13:AH25,"2"))*AR14+(COUNTIF(L13:Q25,"3")+COUNTIF(AC13:AH25,"3"))*AR15)/((COUNT(L13:Q25)+COUNT(AC13:AH25))*100) -> 0.83333333
B8: Inspections are a snapshot in time and refer only to the practices and documentation observed at the time of the Inspection. It remains the responsibility of the Consultant and Contractor to ensure that all aspects of Health & Safety are suitably managed.
B9: 1 | D9: Good Practice | H9: 2 | I9: Need Improvement | T9: 3 | U9: Fail (Life Threatening Activity) / Comliance with Plan & Procedures | X9: N/A | Y9: Atcitty Not Applicable for this Site Inspection Report
B11: No. | C11: Topic | K11: Wt. | L11: HSE Compliance | S11: No. | T11: Topic | AB11: Wt. | AC11: HSE Compliance
B13: 1 | C13: Access and Egress - (General access to site, segregated from vehicles, / Overhead protection, while entering into the building /Adequate lighting provided when dark or overnight work) | K13: 0.05 | L13: 2 | S13: 14 | T13: Work at Height - (PPE/Fall Protection(Same level, above and blow) / Training / Fall restraint / competency /Safe access & egress to and from work at height / Ladders / Openings (floor/shafts/Provision of emergency rescue) | AB13: 0.05 | AC13: N/A | AP13: 1 | AR13: 100 | AU13: 1
B14: 2 | C14: Traffic Management - (Loading/unloading/sheeting/temp. routes/speed/parking/competence) | K14: 0.03 | L14: 2 | S14: 15 | T14: Scaffolding - (Temp. Scaffolding Work-platform (All types) - qualified scaffolder / Inspection / Tagged / Safe Access/egress / PTW/Falsework & Formwork) | AB14: 0.04 | AC14: N/A | AP14: 2 | AR14: 75 | AU14: 2
B15: 3 | C15: Site Signage - (Project Notice Board & General Signage) | K15: 0.02 | L15: 2 | S15: 16 | T15: Mobile Elevated Work platform (MEWP) - (PTW/competence requirements/conditions/inspections/tagged/training/Full-body harness) | AB15: 0.04 | AC15: N/A | AP15: 3 | AR15: 0 | AU15: 3
B16: 4 | C16: PPE Compliance - (Use, storage, stock, handling & checks - Head, Foot, Eye, Hearing) | K16: 0.05 | L16: 2 | S16: 17 | T16: Excavation & Trenches - (PTW/Edge protection/buffer zone/Slope/Benching/Shoring/Geo-tech report/Atmospheric hazards/Acess&egress/Emergency management / MS&RA/H.E) | AB16: 0.03 | AC16: 2 | AU16: N/A
B17: 5 | C17: Housekeeping - (Material correctly stored/Rubbish cleaned & removed daily/slips & trips hazards) | K17: 0.03 | L17: 2 | S17: 18 | T17: Confined Space - (PTW/Training/competence/Emergency Management/MS & RA/Safe access/egress) | AB17: 0.05 | AC17: N/A
B18: 6 | C18: Storage of Materials - (Transporting, storage, training and use - Combustible / Flammable / Hazardous substances (COSHH) | L18: 1 | S18: 19 | T18: Fire Protection - (Flammable/Oxy. LPG /Combustible separated/FE's/Flashback arrestor/Sparks & slags/Smoking area/PTW/Generators/MS & RA/Emergency Management) | AC18: 1 | AL18: Red | AM18: Serious injury or death (immediately)
B19: 7 | C19: Site Waste Management - (Hazardous waste /Combustible waste / Human waste / Construction waste - asphalt, cable, timber, paving roof sheeting tiles, plastic & bricks) | L19: 1 | S19: 20 | T19: Health & Welfare - (Adequate drinking water/shaded - eating & rest area/washing & sanitary facilities/Certified FA/FA Box & Stock/adequate toilets/Ambulance) | AC19: 2 | AL19: Yellow | AM19: Minor or near miss (3 days to comply)
B20: 8 | C20: Health Surveillance - (Expose to excessive noise/vibration/dust/silica/CO/cement/radiation/extreme weather condition) | K20: 0.03 | L20: 2 | S20: 21 | T20: Environmental Incident Measures - (Spill/ Leakage / Concrete wash / vehicle & eqpts. wash / waste disposal/Sewers and drains/emissions/Emergency Management/Training/site run-off water) | AB20: 0.05 | AC20: 2 | AL20: Green | AM20: No issues
B21: 9 | C21: Electrical Safety - (Electrical qualified /RCD/GFCI/Industrial Cocket/LOTO/Cable-overhung or buried/Cords in good condition/current inspection tag) | K21: 0.05 | L21: 2 | S21: 22 | T21: HSE Communications & Meetings - (Schedule HSE Meetings/Safety Committee meetings/Alerts / Lesson learned/Safety Bulletin contains latest HSE KPI) | AB21: 0.05 | AC21: 2
B22: 10 | C22: Tools & Equipment - (Includes, powered, hydraulic & pneumatic/Guards in place/Properly stored/RCD Protection/Earthed/Good condition & tagged) | K22: 0.03 | L22: 1 | S22: 23 | T22: HSE Plan & Associated Procedures - (Approved updated HSE Plan/ CEMP/HAZComm/Procedures/Standards/Project Safety Risk Register) | AB22: 0.03 | AC22: 1 | AL22: 26 points > 4 minors then is it’s a serious issue
B23: 11 | C23: Manual Handling - (Lifting/loading/pulling/pushing/twisting/awkward posture/repetitive task/frequent and prolong physical effort/Reasonable practicable use of mechanical aid) | K23: 0.03 | L23: 2 | S23: 24 | T23: Health, Safety & Environment Incident reporting - (Review of HSE Statistics, Reporting of Unsafe Act & Conditions/ Reporting of Near Miss incident/Reporting of FA cases/Record MT cases) | AB23: 0.03 | AC23: 1
B24: 12 | C24: Vehicle and mobile equipment / Plant - (dumpers; excavators, cranes, piling rigs, grader, roller, loaders/condition/KSA License/certification) | K24: 0.05 | L24: 2 | S24: 25 | T24: HSE Awareness, Training & Competence - (Policy /Objective & targets/Information, training/Climatic condition awareness/Reponses in emergency situation/ Safety Behavior Observation) | AB24: 0.04 | AC24: 2
B25: 13 | C25: Lifting Operations & Rigging - (Lifting Plan/Lifting devices & gears/PTW/Condition/3rd party certification/bank-man/rigger/slingers/man-basket/inspection record/tagged) | L25: N/A | S25: 26 | T25: Project Leadership Site Tours - (Provide evidence of proactive safety performance/Deficient discovered discussed/Positive feedback/Workers resolving safety issues) | AC25: 1
B27: Prepared by: | G27: Abdul kalim | S27: Sent to MODON PM: | X27: Engr.Ziyad Al Shabbat
B28: Safety Results
B29: 1 | D29: =COUNTIF(L13:Q26,"1")+COUNTIF(AB13:AG26,"1") -> 7 | I29: 2 | L29: =COUNTIF(L13:Q26,"2")+COUNTIF(AB13:AG26,"2") -> 14 | U29: 3 | W29: =COUNTIF(L13:Q26,"3")+COUNTIF(AB13:AG26,"3") -> 0

Sheet Major Quantities
A1: MAJOR QUANTITIES
A2: BOQ Number | B2: Description of Item | C2: Total Quantity | D2: Unit of Measurement | E2: Plan To Date | F2: Actual To Date | G2: Excecuted on site | H2: Remaining Total | I2: Variance
A3: B1.32 11 13.01 | B3: Subgrade | C3: 20530 | D3: m3 | F3: 15000 | G3: 15000 | H3: =C3-F3 -> 5530
A4: B1.32 11 23.01 | B4: Aggregate base course | C4: 16375.94 | D4: m3 | F4: 9875.94 | G4: 4625 | H4: =C4-F4 -> 6500
A5: B4.33 31 23.01 | B5: HDPE pipe | C5: 5808 | D5: m | F5: 5808 | H5: =C5-F5 -> 0 | I5: =E5-H5 -> 0
A6: B1.32 12 16.01 | B6: Asphalt | C6: 13360 | D6: m3 | F6: 573 | G6: 573 | H6: =C6-F6 -> 12787
A7: B1.32 14 13.13.01 | B7: Interlock | C7: 27900 | D7: m2 | F7: 0 | H7: =C7-F7 -> 27900
A8: B1.32 16 13.23.01 | B8: Curbstone | C8: 20555 | D8: m2 | F8: 0 | H8: =C8-F8 -> 20555
A9: B2.31 23 00.01 | B9: Medium Voltage cables | C9: 7120 | D9: m | F9: 0 | H9: =C9-F9 -> 7120
A10: B2.33 71 00 02.01 | B10: Low Voltage Cables, Copper & Aluminum, | C10: 7500 | D10: m | F10: 7500 | H10: =C10-F10 -> 0
A11: 31 00 00 | B11: Canopy | C11: 4000 | D11: m | F11: 0 | H11: =C11-F11 -> 4000
A12: 03 00 00 | B12: Platform | C12: 4000 | D12: m2 | F12: 0 | H12: =C12-F12 -> 4000
A13: B4.05 52 00.01 | B13: Metal Handrail | C13: 440 | D13: m | F13: 0 | H13: =C13-F13 -> 440
A14: B2.26 56 19.01 | B14: Lighting Luminaire | C14: 116 | D14: Unit | F14: 0 | H14: =C14-F14 -> 116

Sheet Invoice Log
B1: Weekly Progress Report - Invoice Log | AK1: Y
B2: Project Value | L2: Payment Status | T2: Invoices Summary | AD2: Average Invoices durations | AK2: N
B3: Original Contract Value | F3: 33090825 | H3: O&M Value | J3: 0 | L3: Advance Payment % | N3: 0 | P3: Advance Payment (SAR) | R3: =F3*N3 -> 0 | T3: No of Submitted Invoices | V3: =MAX($C$9:$C$39) -> 2 | X3: Submitted Invoices (SAR) | Z3: =SUM(F9:F39) -> 3048399.3 | AB3: Submiited Invoice Peroid | AD3: CM / PgM Average Approval duration | AF3: 0 | AH3: Average Invoice Value | AI3: 0
B4: Revised Contract Value | F4: 0 | H4: Revised O&M Value | J4: 0 | L4: Retention % | N4: 0 | P4: Retention (SAR) | R4: =F3*N4 -> 0 | T4: No of Approved Invoices (CM) | V4: =COUNTIF($O$9:$O$52,"Y") -> 0 | X4: Approved Invoices (CM) (SAR) | Z4: =SUMIF($O$9:$O$39,"Y",$K$9:$K$39) -> 0 | AD4: MODON PM & Accounts Average Approval duration | AF4: 0
B5: Estimate At Completion Value | F5: 33090825 | H5: Submitted Invoices (Gross Value) | J5: =SUM(F9:F51) -> 3048399.3 | L5: Penalties and deduction % | N5: =J6/F3 -> -6.0439714e-05 | P5: AP Recovery (SAR) | R5: =SUM(G9:G51) -> 0 | T5: No of Approved Invoices (PM) | V5: =COUNTIF($S$9:$S$52,"Y") -> 0 | X5: Approved Invoices (PM) (SAR) | Z5: =SUMIF($S$9:$S$39,"Y",$K$9:$K$39) -> 0 | AB5: Invoice Submitted Compared to Contract Value | AC5: =Z3/F4 -> #DIV/0! | AD5: Payments Average Duration | AF5: 0
B6: Potential Changes | F6: 0 | H6: Total Deduction | J6: =J9+G9 -> -2000 | L6: Penalties and deduction (SAR) | N6: =SUM(J9:J51) -> -2000 | P6: Retention Cumulative (SAR) | R6: =SUM(H9:H51) -> 0 | T6: No of Paid Invoices | V6: =COUNTA(Y9:Y52) -> 0 | X6: Paid Invoices (SAR) | Z6: =SUM(Z9:Z39) -> 0 | AD6: Invoices Average total Duration | AF6: =IFERROR(AVERAGE(AD9:AD52),"")
B7: Invoice Reference | F7: Invoice Value | K7: Period Covered | N7: CM / PgM Approval Timeline | R7: Modon PM & Accounts Approval | Y7: Payment Status | AD7: Total Invoice Duration | AE7: Remarks
B8: # | C8: Invoice No. | D8: Doc Control reference | E8: Submittal Rev. # | F8: Gross Value | G8: AP Recovery | H8: Retention | I8: VAT 5%/15% | J8: Deduction / Penalties | K8: Amount (net) | L8: Start Date | M8: End Date | N8: Date to CM / PgM | O8: CM / PgM Approval (Yes/No) | P8: CM / PgM Reply Date | Q8: Days Elapsed | R8: Date to PM | S8: PM Approval (Yes/No) | T8: PM Reply Date | U8: Date to Accounts | V8: Accounts Approval (Yes/No) | W8: Accounts Approval Date | X8: Days Elapsed | Y8: Date Paid | Z8: Amount Paid | AA8: Paid % | AB8: Payment Period (d) | AC8: Amount Pending
